<?xml version='1.0' encoding='utf-8'?>
<robot name="excavator">
  <link name="base_footprint" />
  <joint name="base_footprint_joint" type="fixed">
    <parent link="base_footprint" />
    <child link="1_base" />
  </joint>
  <link name="1_base">
    <inertial>
      <origin xyz="-0.018171 -0.0017721 0.19446" rpy="0 0 0" />
      <mass value="2592.7" />
      <inertia ixx="1069.7" ixy="0.085575" ixz="-2.7007" iyy="689.73" iyz="0.014558" izz="1627.6" />
    </inertial>
    <visual>
      <origin xyz="0 0 0" rpy="0 0 0" />
      <geometry>
        <mesh filename="package://excavator/meshes/1_base.STL" />
      </geometry>
      <material name="">
        <color rgba="0.79216 0.81961 0.93333 1" />
      </material>
    </visual>
    <collision>
      <origin xyz="0 0 0" rpy="0 0 0" />
      <geometry>
        <mesh filename="package://excavator/meshes/1_base.STL" />
      </geometry>
    </collision>
  </link>
  <link name="2_swing">
    <inertial>
      <origin xyz="-0.83549 0.21412 0.58331" rpy="0 0 0" />
      <mass value="7793.2" />
      <inertia ixx="5729.6" ixy="-1496.5" ixz="-549.49" iyy="8160.3" iyz="-525.9" izz="11992" />
    </inertial>
    <visual>
      <origin xyz="0 0 0" rpy="0 0 0" />
      <geometry>
        <mesh filename="package://excavator/meshes/2_swing.STL" />
      </geometry>
      <material name="">
        <color rgba="1 0.74902 0 1" />
      </material>
    </visual>
    <collision>
      <origin xyz="0 0 0" rpy="0 0 0" />
      <geometry>
        <mesh filename="package://excavator/meshes/2_swing.STL" />
      </geometry>
    </collision>
  </link>
  <joint name="j1_swing" type="continuous">
    <origin xyz="0 0 0.72" rpy="0 0 0" />
    <parent link="1_base" />
    <child link="2_swing" />
    <axis xyz="0 0 -1" />
  </joint>
  <link name="3_boom">
    <inertial>
      <origin xyz="2.2911 3.7748E-15 1.2825" rpy="0 0 0" />
      <mass value="1440.8" />
      <inertia ixx="321.25" ixy="5.2749E-13" ixz="-661.98" iyy="3009.3" iyz="1.7997E-13" izz="2727.5" />
    </inertial>
    <visual>
      <origin xyz="0 0 0" rpy="0 0 0" />
      <geometry>
        <mesh filename="package://excavator/meshes/3_boom.STL" />
      </geometry>
      <material name="">
        <color rgba="1 0.49804 0 1" />
      </material>
    </visual>
    <collision>
      <origin xyz="0 0 0" rpy="0 0 0" />
      <geometry>
        <mesh filename="package://excavator/meshes/3_boom.STL" />
      </geometry>
    </collision>
  </link>
  <joint name="j2_boom" type="revolute">
    <origin xyz="-0.009 0 1.0372" rpy="0 0 0" />
    <parent link="2_swing" />
    <child link="3_boom" />
    <axis xyz="0 1 0" />
    <limit lower="-0.9" upper="0.3" effort="0" velocity="1" />
  </joint>
  <link name="6_stick">
    <inertial>
      <origin xyz="0.9223 6.2172E-15 0.24134" rpy="0 0 0" />
      <mass value="600.4" />
      <inertia ixx="26.656" ixy="-1.7876E-14" ixz="15.684" iyy="564.47" iyz="4.8971E-14" izz="545.68" />
    </inertial>
    <visual>
      <origin xyz="0 0 0" rpy="0 0 0" />
      <geometry>
        <mesh filename="package://excavator/meshes/6_stick.STL" />
      </geometry>
      <material name="">
        <color rgba="0 0.66667 0 1" />
      </material>
    </visual>
    <collision>
      <origin xyz="0 0 0" rpy="0 0 0" />
      <geometry>
        <mesh filename="package://excavator/meshes/6_stick.STL" />
      </geometry>
    </collision>
  </link>
  <joint name="j3_stick" type="revolute">
    <origin xyz="5.4177 0 1.706" rpy="0 1.2726 0" />
    <parent link="3_boom" />
    <child link="6_stick" />
    <axis xyz="0 1 0" />
    <limit lower="-0.8" upper="1.0" effort="0" velocity="1" />
  </joint>
  <link name="8_bucket">
    <inertial>
      <origin xyz="0.72017 3.3307E-15 0.569" rpy="0 0 0" />
      <mass value="359.5" />
      <inertia ixx="94.627" ixy="4.1355E-14" ixz="-4.7801" iyy="138.37" iyz="7.1336E-14" izz="169.06" />
    </inertial>
    <visual>
      <origin xyz="0 0 0" rpy="0 0 0" />
      <geometry>
        <mesh filename="package://excavator/meshes/8_bucket.STL" />
      </geometry>
      <material name="">
        <color rgba="0.52941 0.54902 0.54902 1" />
      </material>
    </visual>
    <collision>
      <origin xyz="0 0 0" rpy="0 0 0" />
      <geometry>
        <mesh filename="package://excavator/meshes/8_bucket.STL" />
      </geometry>
    </collision>
  </link>
  <joint name="j4_bucket" type="revolute">
    <origin xyz="2.9111 0 0.15097" rpy="0 1.4717 0" />
    <parent link="6_stick" />
    <child link="8_bucket" />
    <axis xyz="0 1 0" />
    <limit lower="-2.1" upper="0.6" effort="0" velocity="1" />
  </joint>
</robot>
